# Part 14 예외 처리
* [14.1 예외처리의 기본](#141-예외처리의-기본)
* [14.2 예외처리와 스택 되감기](#142-예외처리와-스택-되감기)
* [14.3 예외 클래스와 상속](#143-예외-클래스와-상속)
* [14.4 exception 소개](#144-exception-소개)
* [14.5 함수 try](#145-함수-try)
* [14.6 예외처리의 위험성과 단점](#146-예외처리의-위험성과-단점)

[뒤로](https://github.com/hhhan0315/Algorithm)

## 14.1 예외처리의 기본
```c
#include <iostream>
using namespace std;

int main()
{
	// try, catch, throw
	double x;
	cin >> x;

	try
	{
		if (x < 0.0) throw std::string("Negative input");	// throw : 예외를 던진다.
		cout << std::sqrt(x) << endl;
	}
	catch (std::string error_message)	// catch : 예외를 잡는다.
	{
		cout << error_message << endl;
	}

	return 0;
}
```

[위로](#part-14-예외-처리)

## 14.2 예외처리와 스택 되감기
```c
#include <iostream>
using namespace std;

void last()
{
	cout << "last " << endl;
	cout << "Throws exception" << endl;
	throw - 1;
	cout << "End last" << endl;
}

void third()
{
	cout << "third" << endl;
	last();
	cout << "End third" << endl;
}

void second()
{
	cout << "second" << endl;
	try
	{
		third();
	}
	catch (double)
	{
		cerr << "second caught double exception" << endl;
	}
	cout << "End second" << endl;
}

void first()
{
	cout << "first" << endl;
	try
	{
		second();
	}
	catch (int)
	{
		cerr << "first caught int exception" << endl;
	}
	cout << "End first" << endl;
}

int main()
{
	cout << "Start" << endl;

	try
	{
		first();
	}
	catch (int)
	{
		cerr << "main caught int exception" << endl;
	}
	catch (...)	// 다 받는다.
	{
		cerr << "main caught ellipses exception" << endl;
	}

	// throw 보낸걸 catch로 잡지 못하면 계속 throw 한다.

	return 0;
}
```

[위로](#part-14-예외-처리)

## 14.3 예외 클래스와 상속
```c
#include <iostream>
using namespace std;

class Exception
{
public:
	void report()
	{
		cerr << "Exception report" << endl;
	}
};

class ArrayException : public Exception
{
public:
	void report()
	{
		cerr << "Array exception" << endl;
	}
};

class MyArray
{
private:
	int m_data[5];
public:
	int& operator [] (const int& index)
	{
		//if (index < 0 || index >= 5) throw - 1;
		if (index < 0 || index >= 5) throw ArrayException();
		return m_data[index];
	}
};

void doSomething()
{
	MyArray my_array;

	try
	{
		my_array[100];
	}
	catch (const int& x)
	{
		cerr << "Exception " << x << endl;
	}
	//catch (ArrayException & e)	// 자식 클래스가 먼저 나오도록 순서 교체.
	//{
	//	cout << "doSomething()" << endl;
	//	e.report();
	//	throw e;	// 다시 throw
	//}
	catch (Exception & e)
	{
		cout << "doSomething()" << endl;
		e.report();
		throw;
		// throw e 는 exception report 호출 (객체 잘림 발생)
		// thorw 는 array exception 호출
	}
}

int main()
{
	try
	{
		doSomething();
	}
	catch (ArrayException & e)
	{
		cout << "main()" << endl;
		e.report();
	}
	catch (Exception & e)
	{
		cout << "main()" << endl;
		e.report();
	}

	return 0;
}
```

[위로](#part-14-예외-처리)

## 14.4 exception 소개
```c
#include <iostream>
#include <exception>
#include <string>
using namespace std;

class CustomException : public std::exception      // custom 만들 때 what을 override 해주어야함.
{
public:
	const char* what() const noexcept override // noexcept : c++11 이상 들어가야함.
	{
		return "Custom exception";
	}
};

int main()
{
	try
	{
		//std::string s;
		//s.resize(-1);
		//throw std::runtime_error("Bad thing happened");	// 일부러 throw
		throw CustomException();
	}
	catch (std::exception & exception)
	{
		std::cout << typeid(exception).name() << std::endl;
		std::cerr << exception.what() << std::endl;
	}

	return 0;
}
```

[위로](#part-14-예외-처리)

## 14.5 함수 try
```c
#include <iostream>
using namespace std;

class A
{
private:
	int m_x;
public:
	A(int x) : m_x(x)
	{
		if (x <= 0) throw 1;
	}
};

class B : public A
{
public:
	/*B(int x)
		:A(x)
	{}*/

	// 생성자에서 try 를 사용하면 생성자의 catch에서 잡고 main의 catch에서 또 잡는다.(특징)
	B(int x) try : A(x)
	{}
	catch (...)
	{
		cout << "Catch in B constructor " << endl;
		//throw;	// throw가 주석처리지만 있는 것처럼 동작한다.
	}
};

int main()
{
	try
	{
		B b(0);
	}
	catch (...)
	{
		cout << "Catch in main()" << endl;
	}

	return 0;
}
```

[위로](#part-14-예외-처리)

## 14.6 예외처리의 위험성과 단점
```c
#include <iostream>
#include <memory>
using namespace std;

class A
{
public:
	~A()	// destructor 에서는 예외를 던지지 못한다.
	{
		// throw "error";	// 금지
	}
};

int main()
{
	try
	{
		int* i = new int[1000000];
		unique_ptr<int> up_i(i);	// 스마트 포인터 (실전에서 잘 사용함)
		// 알아서 delete도 해주고 throw 해주는 경우에도 delete 해줌.

		throw "error";
		//delete[] i;	// 메모리 누수 가능성 // unique_ptr 등장으로 delete 주석 처리 가능.

		A a;
	}
	catch (...)
	{
		cout << "Catch" << endl;
	}
	// 동적 서버 10만명 등 자주 사용하는 루프 안에 try, catch 사용 시 아주 느려진다.

	return 0;
}
```

[위로](#part-14-예외-처리)
